Workbook
Name ___SH2: #REF!
Name ___SH2: #REF!
Name ___SH2: #REF!
Name ___SH2: #REF!
Name ___SH2: #REF!
Name ___SH2: #REF!
Name ___SH2: #REF!
Name ___SH2: #REF!
Name ___SH2: #REF!
Name ___SH2: #REF!
Name ___SH2: #REF!
Name ___SH2: #REF!
Name ___SH2: #REF!
Name ___SH2: #REF!
Name ___SH2: #REF!
Name ___SH2: #REF!
Name ___SH2: #REF!
Name ___SH2: #REF!
Name ___SH2: #REF!
Name ___SH2: #REF!
Name __SH2: #REF!
Name __SH2: #REF!
Name __SH2: #REF!
Name __SH2: #REF!
Name __SH2: #REF!
Name __SH2: #REF!
Name __SH2: #REF!
Name __SH2: #REF!
Name __SH2: #REF!
Name __SH2: #REF!
Name __SH2: #REF!
Name __SH2: #REF!
Name __SH2: #REF!
Name __SH2: #REF!
Name __SH2: #REF!
Name __SH2: #REF!
Name __SH2: #REF!
Name __SH2: #REF!
Name __SH2: #REF!
Name __SH2: #REF!
Name _SH2: #REF!
Name _SH2: #REF!
Name _SH2: #REF!
Name _SH2: #REF!
Name _SH2: #REF!
Name _SH2: #REF!
Name _SH2: #REF!
Name _SH2: #REF!
Name _SH2: #REF!
Name _SH2: #REF!
Name _SH2: #REF!
Name _SH2: #REF!
Name _SH2: #REF!
Name _SH2: #REF!
Name _SH2: #REF!
Name _SH2: #REF!
Name _SH2: #REF!
Name _SH2: #REF!
Name _SH2: #REF!
Name _SH2: #REF!

Sheet COVER
E2: GHANA STATISTICAL SERVICE
E3: Statistics for Development and Progress
H6: Quarterly GDP Bullletin
C10: SEPTEMBER 2026 EDITION
B35: Ghana Statistical Service (GSS)
B36: P.O. Box GP 1098, Accra
B37: www.statsghana.gov.gh

Sheet Table of Content
B3: Table of Content
B4: Notes………...……………………………………………………………………………………………………….... 1
B5: Appendix discription..…..………………………………………………………………………………………. 2
B6: Appendices ………………………………………………………………………………………………………….. 3

Sheet Notes
A1: NOTES
A3: Forthcoming issues
B4: Issue | C4: Expected Date of Publication
B5: Second Quarter of 2026 | C5: 46274
B6: Third Quarter of 2026 | C6: 46365
B7: Fourth Quarter of 2026 | C7: 46456
A9: Explanatory notes
A11: Introduction
A12: This publication contains final rebased quarterly GDP estimates for 2006 Q1 to 2023Q4, revised estimates for
A13: 2024Q1 to 2026Q1 and provisional estimates for 2026Q2.
A15: Gross Domestic Product (GDP) is Ghana’s official measure of economic growth.There are three different approaches for calculating GDP. These are the production approach, the expenditure approach and the income approach. The production and expenditure approaches are used to calculate Ghana’s GDP on a quarterly basis.
A16: The bulletin contains 30 Tables: Appendix 1 to 4: Quarterly GDP at Current Prices by Economic Activity and respective Sectoral Distribution; Appendix 5: Quarterly Deflators by Economi Activity; Appendix 6 to 15: Quarterly GDP at Constant 2013 prices by Economic Activity and Sectoral Growth rates; Appendix 16 to 25: Seasonally Adjusted Quarterly GDP at Constant 2013 Prices by Economic Activity and Sectoral growth rates. Appendix 26: Distribtion of GDP, Appendix 27: Contribution to Growth. Appendix 28 to 30: Half Year Current GDP, Constant GDP and Contribution to Growth.
A17: For more information about GDP and the national accounts, go to Ghana Statistical Service website (www.statsghana.gov.gh).
A19: Sources and Methods
A20: This Statistical Release contains independently compiled quarterly estimates of the Gross Domestic Product (GDP) from the first quarter of 2013 onwards. The estimates are based on the 2008 System of National Accounts (SNA), International Standard Industrial Classification Revision 4 published by the United Nations and Quarterly National Accounts Manual: Concepts, Data Sources and Compilation by International Monetary Fund (IMF). This means that the methodology, concepts and classifications are in accordance with the guidelines and recommendations of an internationally agreed system of national accounts. The estimates of real GDP use 2013 as the base year.
A22: Methodology
A24: Short-term indicators are used to estimate the quarterly GDP (See IMF's Quarterly National Accounts Manual: Concepts, Data sources, and Compilation) from which annual GDP estimates are calculated independently from the quarterly estimates. Alternatively, annual GDP estimates are derived as the sum of the GDP for the four quarters of the year.
A26: Seasonal adjustment
... A35: Irregular: Irregular revisions occur for example, as a result of methodological changes. Note that, as far as possible, revisions of this nature are incorporated to coincide with the annual cycle of revisions outlined above.

Sheet Table Description
B3: Appendix description
B4: Appendix 1- Quarterly Value Added and Gross Domestic Product at Current Prices by Economic Activity and Respective Sectoral Distribution
B5: Appendix 2 - Agriculture: Value Added by activity at Current Prices
B6: Appendix 3- Industry: Value Added by Activity at Current Prices
B7: Appendix 4 - Services: Value Added by Activity at Current Prices
B8: Appendix 5 - Quarterly Deflators by Economic Activity
B9: Appendix 6 - Quarterly Value Added and Gross Domestic Product at Constant 2013 Prices by Economic Activity
B10: Appendix 7 - Agriculture: Quarterly Value Added at Constant 2013 Prices by Economic Activity
B11: Appendix 8 - Agriculture: Quarterly Value Added at Constant 2013 Prices by Economic Activity (Quarter-on-Quarter Change)
B12: Appendix 9 - Agriculture: Quarterly Value dded at Constant 2013 Prices by Economic Activity (Year-on-Year Change)
B13: Appendix 10 - Industry: Quarterly Value Added at Constant 2013 Prices by Economic Activity
B14: Appendix 11 - Industry: Quarterly Value Added at Constant 2013 Prices by Economic Activity (Quarter-on-Quarter Change)
... B33: Appendix 30: Half Year Contribution to Growth

Sheet tables
A4: Tables
A7: ='T1'!B1 -> Table 1 - Quarterly Value Added by Activity and Gross Domestic Product at Constant 2006 Prices (GHc Million)
A9: ='T2'!B1 -> Table 2 - Percentage change (quarter-on-quarter) in the quarterly value added by Activity at 2006 constant prices
A11: ='T3'!B1 -> Table 3 - Percentage Changes (Year-on-Year) in the Quarterly Value Added by Activity and Gross Domestic Product at Constant 2006 Prices
A13: ='T4'!B1 -> Table 4 - Seasonal Adjusted Quarterly Gross Value Added by Activity at Constant 2006 Prices (GHc Million)
A15: ='T5'!B1 -> Table 5 - Percentage change (quarter-on-quarter) Seasonal Adjusted Quarterly Gross Value Added by Activity at Constant 2006 Prices
A17: ='T6'!B1 -> Table 6 - Percentage Changes (Year-on-Year) in the Seasonal Adjusted Quarterly Value Added by Activity and Gross Domestic Product at Constant 2006 Prices
A19: ='Current GDP_All'!A1 -> Appendix 1- Quarterly Value Added and Gross Domestic Product at Current Prices by Economic Activity and Respective Sectoral Distribution
A21: =Tsum2!B1 -> Table 2 - Seasonal Adjusted Quarterly Gross Domestic Product at Constant 2006 Prices
B40: 5

Sheet T1
B1: Table 1 - Quarterly Value Added by Activity and Gross Domestic Product at Constant 2006 Prices (GHc Million)
D2: Agriculture Sector | H2: Industry Sector | M2: Services Sector
B3: Year | C3: Quarter | D3: Crops & Cocoa | E3: Livestock | F3: Forestry | G3: Fishing | H3: Mining and Quarrying | I3: Manufacturing | J3: Electricity | K3: Water & Sewerage | L3: Construction | M3: Trade; Repair Of Vehicles, Household Goods | N3: Hotels And Restaurants | O3: Transport & Storage | P3: Information & Communication | Q3: Financial & Insurance Activities | R3: Real Estate Activities | S3: Business & other Services Activities | T3: Public Administration | U3: Education | V3: Health | W3: Other Personal Service Activities | X3: Total Value Added at Basis Prices | Y3: Net Taxes | Z3: GDP at Constant Prices | AC3: Agric | AD3: Ind | AE3: Serv | AF3: controle
B4: 2006 | D4: 3793.682 | E4: 437.09725 | F4: 736.00309 | G4: 448.25153 | H4: 497.4452 | I4: 1823.4833 | J4: 142.71912 | K4: 224.36136 | L4: 1016.2744 | M4: 1140.6992 | N4: 894.08203 | O4: 2357.2217 | P4: 483.03723 | Q4: 472.8561 | R4: 391.4 | S4: 522.52707 | T4: 862.13807 | U4: 654.95995 | V4: 249.83921 | W4: 661.61553 | X4: =D4+E4+F4+G4+H4+I4+J4+K4+L4+M4+N4+O4+P4+Q4+R4+S4+T4+U4+V4+W4 -> 17809.693 | Y4: 895.36021 | Z4: 18705.054 | AC4: =D4+E4+F4+G4 -> 5415.0338 | AD4: =H4+I4+J4+K4+L4 -> 3704.2834 | AE4: =I4+J4+K4+L4+M4 -> 4347.5374 | AF4: =AC4+AD4+AE4 -> 13466.855
B5: 2007 | D5: 3742.596 | E5: 457.77915 | F5: 705.88127 | G5: 415.76563 | H5: 531.5803 | I5: 1801.3123 | J5: 118.15348 | K5: 226.96637 | L5: 1251.5619 | M5: 1202.6217 | N5: 916.59233 | O5: 2573.4037 | P5: 502.84176 | Q5: 559.76897 | R5: 400.7936 | S5: 542.72237 | T5: 959.55967 | U5: 720.45595 | V5: 259.27272 | W5: 720.31678 | X5: =D5+E5+F5+G5+H5+I5+J5+K5+L5+M5+N5+O5+P5+Q5+R5+S5+T5+U5+V5+W5 -> 18609.946 | Y5: 1303.4106 | Z5: 19913.357 | AC5: =D5+E5+F5+G5 -> 5322.0221 | AD5: =H5+I5+J5+K5+L5 -> 3929.5743 | AE5: =I5+J5+K5+L5+M5 -> 4600.6157 | AF5: =AC5+AD5+AE5 -> 13852.212
B6: 2008 | D6: 4064.4593 | E6: 481.14404 | F6: 682.44508 | G6: 488.02892 | H6: 544.44121 | I6: 1867.9694 | J6: 141.10302 | K6: 228.8878 | L6: 1739.4644 | M6: 1316.9257 | N6: 999.77813 | O6: 2671.91 | P6: 600.8959 | Q6: 620.12127 | R6: 410.41265 | S6: 532.78696 | T6: 1081.751 | U6: 814.29858 | V6: 270.78237 | W6: 786.30765 | X6: =D6+E6+F6+G6+H6+I6+J6+K6+L6+M6+N6+O6+P6+Q6+R6+S6+T6+U6+V6+W6 -> 20343.913 | Y6: 1248.2662 | Z6: 21592.18 | AC6: =D6+E6+F6+G6 -> 5716.0774 | AD6: =H6+I6+J6+K6+L6 -> 4521.8658 | AE6: =I6+J6+K6+L6+M6 -> 5294.3503 | AF6: =AC6+AD6+AE6 -> 15532.294
B7: 2009 | D7: 4479.4263 | E7: 502.15329 | F7: 687.36015 | G7: 460.15533 | H7: 581.2 | I7: 1843.5799 | J7: 151.69194 | K7: 246.39795 | L7: 1901.8527 | M7: 1387.931 | N7: 962.00084 | O7: 2790.1363 | P7: 624.16472 | Q7: 677.93817 | R7: 420.26255 | S7: 524.52844 | T7: 1208.1799 | U7: 914.89016 | V7: 311.81225 | W7: 845.05032 | X7: =D7+E7+F7+G7+H7+I7+J7+K7+L7+M7+N7+O7+P7+Q7+R7+S7+T7+U7+V7+W7 -> 21520.712 | Y7: 933.77662 | Z7: 22454.489 | AC7: =D7+E7+F7+G7 -> 6129.095 | AD7: =H7+I7+J7+K7+L7 -> 4724.7225 | AE7: =I7+J7+K7+L7+M7 -> 5531.4535 | AF7: =AC7+AD7+AE7 -> 16385.271
B8: 2010 | D8: 4703.4 | E8: 525.5 | F8: 756.58618 | G8: 467.01505 | H8: 625.61986 | I8: 1983.7 | J8: 170.28972 | K8: 259.36777 | L8: 1949.3991 | M8: 1573.0945 | N8: 987.85721 | O8: 3014.308 | P8: 776.90602 | Q8: 791.49056 | R8: 430.34885 | S8: 645.7 | T8: 1248.9614 | U8: 963.21808 | V8: 346.86159 | W8: 935.5 | X8: =D8+E8+F8+G8+H8+I8+J8+K8+L8+M8+N8+O8+P8+Q8+R8+S8+T8+U8+V8+W8 -> 23155.124 | Y8: 1032.2005 | Z8: 24187.324 | AC8: =D8+E8+F8+G8 -> 6452.5012 | AD8: =H8+I8+J8+K8+L8 -> 4988.3764 | AE8: =I8+J8+K8+L8+M8 -> 5935.8511 | AF8: =AC8+AD8+AE8 -> 17376.729
B10: 2006 | C10: 1 | D10: =#REF! -> #REF! | E10: =#REF! -> #REF! | F10: =#REF! -> #REF! | G10: =#REF! -> #REF! | H10: =#REF! -> #REF! | I10: =#REF! -> #REF! | J10: =#REF! -> #REF! | K10: =#REF! -> #REF! | ... W10: =#REF! -> #REF! | X10: =D10+E10+F10+G10+H10+I10+J10+K10+L10+M10+N10+O10+P10+Q10+R10+S10+T10+U10+V10+W10 -> #REF! | Y10: =#REF! -> #REF! | Z10: =X10+Y10 -> #REF! | AC10: =D10+E10+F10+G10 -> #REF! | AD10: =H10+I10+J10+K10+L10 -> #REF! | AE10: =I10+J10+K10+L10+M10 -> #REF! | AF10: =AC10+AD10+AE10 -> #REF! | AG10: =AF10-X10 -> #REF!
C11: 2 | D11: =#REF! -> #REF! | E11: =#REF! -> #REF! | F11: =#REF! -> #REF! | G11: =#REF! -> #REF! | H11: =#REF! -> #REF! | I11: =#REF! -> #REF! | J11: =#REF! -> #REF! | K11: =#REF! -> #REF! | ... W11: =#REF! -> #REF! | X11: =D11+E11+F11+G11+H11+I11+J11+K11+L11+M11+N11+O11+P11+Q11+R11+S11+T11+U11+V11+W11 -> #REF! | Y11: =#REF! -> #REF! | Z11: =X11+Y11 -> #REF! | AC11: =D11+E11+F11+G11 -> #REF! | AD11: =H11+I11+J11+K11+L11 -> #REF! | AE11: =M11+N11+O11+P11+Q11+R11+S11+T11+U11+V11+W11 -> #REF! | AF11: =AC11+AD11+AE11 -> #REF! | AG11: =AF11-X11 -> #REF!
C12: 3 | D12: =#REF! -> #REF! | E12: =#REF! -> #REF! | F12: =#REF! -> #REF! | G12: =#REF! -> #REF! | H12: =#REF! -> #REF! | I12: =#REF! -> #REF! | J12: =#REF! -> #REF! | K12: =#REF! -> #REF! | ... W12: =#REF! -> #REF! | X12: =D12+E12+F12+G12+H12+I12+J12+K12+L12+M12+N12+O12+P12+Q12+R12+S12+T12+U12+V12+W12 -> #REF! | Y12: =#REF! -> #REF! | Z12: =X12+Y12 -> #REF! | AC12: =D12+E12+F12+G12 -> #REF! | AD12: =H12+I12+J12+K12+L12 -> #REF! | AE12: =M12+N12+O12+P12+Q12+R12+S12+T12+U12+V12+W12 -> #REF! | AF12: =AC12+AD12+AE12 -> #REF! | AG12: =AF12-X12 -> #REF!
C13: 4 | D13: =#REF! -> #REF! | E13: =#REF! -> #REF! | F13: =#REF! -> #REF! | G13: =#REF! -> #REF! | H13: =#REF! -> #REF! | I13: =#REF! -> #REF! | J13: =#REF! -> #REF! | K13: =#REF! -> #REF! | ... W13: =#REF! -> #REF! | X13: =D13+E13+F13+G13+H13+I13+J13+K13+L13+M13+N13+O13+P13+Q13+R13+S13+T13+U13+V13+W13 -> #REF! | Y13: =#REF! -> #REF! | Z13: =X13+Y13 -> #REF! | AC13: =D13+E13+F13+G13 -> #REF! | AD13: =H13+I13+J13+K13+L13 -> #REF! | AE13: =M13+N13+O13+P13+Q13+R13+S13+T13+U13+V13+W13 -> #REF! | AF13: =AC13+AD13+AE13 -> #REF! | AG13: =AF13-X13 -> #REF!
B14: 2007 | C14: 1 | D14: =#REF! -> #REF! | E14: =#REF! -> #REF! | F14: =#REF! -> #REF! | G14: =#REF! -> #REF! | H14: =#REF! -> #REF! | I14: =#REF! -> #REF! | J14: =#REF! -> #REF! | K14: =#REF! -> #REF! | ... W14: =#REF! -> #REF! | X14: =D14+E14+F14+G14+H14+I14+J14+K14+L14+M14+N14+O14+P14+Q14+R14+S14+T14+U14+V14+W14 -> #REF! | Y14: =#REF! -> #REF! | Z14: =X14+Y14 -> #REF! | AC14: =D14+E14+F14+G14 -> #REF! | AD14: =H14+I14+J14+K14+L14 -> #REF! | AE14: =M14+N14+O14+P14+Q14+R14+S14+T14+U14+V14+W14 -> #REF! | AF14: =AC14+AD14+AE14 -> #REF! | AG14: =AF14-X14 -> #REF!
C15: 2 | D15: =#REF! -> #REF! | E15: =#REF! -> #REF! | F15: =#REF! -> #REF! | G15: =#REF! -> #REF! | H15: =#REF! -> #REF! | I15: =#REF! -> #REF! | J15: =#REF! -> #REF! | K15: =#REF! -> #REF! | ... W15: =#REF! -> #REF! | X15: =D15+E15+F15+G15+H15+I15+J15+K15+L15+M15+N15+O15+P15+Q15+R15+S15+T15+U15+V15+W15 -> #REF! | Y15: =#REF! -> #REF! | Z15: =X15+Y15 -> #REF! | AC15: =D15+E15+F15+G15 -> #REF! | AD15: =H15+I15+J15+K15+L15 -> #REF! | AE15: =M15+N15+O15+P15+Q15+R15+S15+T15+U15+V15+W15 -> #REF! | AF15: =AC15+AD15+AE15 -> #REF! | AG15: =AF15-X15 -> #REF!
C16: 3 | D16: =#REF! -> #REF! | E16: =#REF! -> #REF! | F16: =#REF! -> #REF! | G16: =#REF! -> #REF! | H16: =#REF! -> #REF! | I16: =#REF! -> #REF! | J16: =#REF! -> #REF! | K16: =#REF! -> #REF! | ... W16: =#REF! -> #REF! | X16: =D16+E16+F16+G16+H16+I16+J16+K16+L16+M16+N16+O16+P16+Q16+R16+S16+T16+U16+V16+W16 -> #REF! | Y16: =#REF! -> #REF! | Z16: =X16+Y16 -> #REF! | AC16: =D16+E16+F16+G16 -> #REF! | AD16: =H16+I16+J16+K16+L16 -> #REF! | AE16: =M16+N16+O16+P16+Q16+R16+S16+T16+U16+V16+W16 -> #REF! | AF16: =AC16+AD16+AE16 -> #REF! | AG16: =AF16-X16 -> #REF!
C17: 4 | D17: =#REF! -> #REF! | E17: =#REF! -> #REF! | F17: =#REF! -> #REF! | G17: =#REF! -> #REF! | H17: =#REF! -> #REF! | I17: =#REF! -> #REF! | J17: =#REF! -> #REF! | K17: =#REF! -> #REF! | ... W17: =#REF! -> #REF! | X17: =D17+E17+F17+G17+H17+I17+J17+K17+L17+M17+N17+O17+P17+Q17+R17+S17+T17+U17+V17+W17 -> #REF! | Y17: =#REF! -> #REF! | Z17: =X17+Y17 -> #REF! | AC17: =D17+E17+F17+G17 -> #REF! | AD17: =H17+I17+J17+K17+L17 -> #REF! | AE17: =M17+N17+O17+P17+Q17+R17+S17+T17+U17+V17+W17 -> #REF! | AF17: =AC17+AD17+AE17 -> #REF! | AG17: =AF17-X17 -> #REF!
B18: 2008 | C18: 1 | D18: =#REF! -> #REF! | E18: =#REF! -> #REF! | F18: =#REF! -> #REF! | G18: =#REF! -> #REF! | H18: =#REF! -> #REF! | I18: =#REF! -> #REF! | J18: =#REF! -> #REF! | K18: =#REF! -> #REF! | ... W18: =#REF! -> #REF! | X18: =D18+E18+F18+G18+H18+I18+J18+K18+L18+M18+N18+O18+P18+Q18+R18+S18+T18+U18+V18+W18 -> #REF! | Y18: =#REF! -> #REF! | Z18: =X18+Y18 -> #REF! | AC18: =D18+E18+F18+G18 -> #REF! | AD18: =H18+I18+J18+K18+L18 -> #REF! | AE18: =M18+N18+O18+P18+Q18+R18+S18+T18+U18+V18+W18 -> #REF! | AF18: =AC18+AD18+AE18 -> #REF! | AG18: =AF18-X18 -> #REF!
C19: 2 | D19: =#REF! -> #REF! | E19: =#REF! -> #REF! | F19: =#REF! -> #REF! | G19: =#REF! -> #REF! | H19: =#REF! -> #REF! | I19: =#REF! -> #REF! | J19: =#REF! -> #REF! | K19: =#REF! -> #REF! | ... W19: =#REF! -> #REF! | X19: =D19+E19+F19+G19+H19+I19+J19+K19+L19+M19+N19+O19+P19+Q19+R19+S19+T19+U19+V19+W19 -> #REF! | Y19: =#REF! -> #REF! | Z19: =X19+Y19 -> #REF! | AC19: =D19+E19+F19+G19 -> #REF! | AD19: =H19+I19+J19+K19+L19 -> #REF! | AE19: =M19+N19+O19+P19+Q19+R19+S19+T19+U19+V19+W19 -> #REF! | AF19: =AC19+AD19+AE19 -> #REF! | AG19: =AF19-X19 -> #REF!
C20: 3 | D20: =#REF! -> #REF! | E20: =#REF! -> #REF! | F20: =#REF! -> #REF! | G20: =#REF! -> #REF! | H20: =#REF! -> #REF! | I20: =#REF! -> #REF! | J20: =#REF! -> #REF! | K20: =#REF! -> #REF! | ... W20: =#REF! -> #REF! | X20: =D20+E20+F20+G20+H20+I20+J20+K20+L20+M20+N20+O20+P20+Q20+R20+S20+T20+U20+V20+W20 -> #REF! | Y20: =#REF! -> #REF! | Z20: =X20+Y20 -> #REF! | AC20: =D20+E20+F20+G20 -> #REF! | AD20: =H20+I20+J20+K20+L20 -> #REF! | AE20: =M20+N20+O20+P20+Q20+R20+S20+T20+U20+V20+W20 -> #REF! | AF20: =AC20+AD20+AE20 -> #REF! | AG20: =AF20-X20 -> #REF!
C21: 4 | D21: =#REF! -> #REF! | E21: =#REF! -> #REF! | F21: =#REF! -> #REF! | G21: =#REF! -> #REF! | H21: =#REF! -> #REF! | I21: =#REF! -> #REF! | J21: =#REF! -> #REF! | K21: =#REF! -> #REF! | ... W21: =#REF! -> #REF! | X21: =D21+E21+F21+G21+H21+I21+J21+K21+L21+M21+N21+O21+P21+Q21+R21+S21+T21+U21+V21+W21 -> #REF! | Y21: =#REF! -> #REF! | Z21: =X21+Y21 -> #REF! | AC21: =D21+E21+F21+G21 -> #REF! | AD21: =H21+I21+J21+K21+L21 -> #REF! | AE21: =M21+N21+O21+P21+Q21+R21+S21+T21+U21+V21+W21 -> #REF! | AF21: =AC21+AD21+AE21 -> #REF! | AG21: =AF21-X21 -> #REF!
B22: 2009 | C22: 1 | D22: =#REF! -> #REF! | E22: =#REF! -> #REF! | F22: =#REF! -> #REF! | G22: =#REF! -> #REF! | H22: =#REF! -> #REF! | I22: =#REF! -> #REF! | J22: =#REF! -> #REF! | K22: =#REF! -> #REF! | ... W22: =#REF! -> #REF! | X22: =D22+E22+F22+G22+H22+I22+J22+K22+L22+M22+N22+O22+P22+Q22+R22+S22+T22+U22+V22+W22 -> #REF! | Y22: =#REF! -> #REF! | Z22: =X22+Y22 -> #REF! | AC22: =D22+E22+F22+G22 -> #REF! | AD22: =H22+I22+J22+K22+L22 -> #REF! | AE22: =M22+N22+O22+P22+Q22+R22+S22+T22+U22+V22+W22 -> #REF! | AF22: =AC22+AD22+AE22 -> #REF! | AG22: =AF22-X22 -> #REF!
C23: 2 | D23: =#REF! -> #REF! | E23: =#REF! -> #REF! | F23: =#REF! -> #REF! | G23: =#REF! -> #REF! | H23: =#REF! -> #REF! | I23: =#REF! -> #REF! | J23: =#REF! -> #REF! | K23: =#REF! -> #REF! | ... W23: =#REF! -> #REF! | X23: =D23+E23+F23+G23+H23+I23+J23+K23+L23+M23+N23+O23+P23+Q23+R23+S23+T23+U23+V23+W23 -> #REF! | Y23: =#REF! -> #REF! | Z23: =X23+Y23 -> #REF! | AC23: =D23+E23+F23+G23 -> #REF! | AD23: =H23+I23+J23+K23+L23 -> #REF! | AE23: =M23+N23+O23+P23+Q23+R23+S23+T23+U23+V23+W23 -> #REF! | AF23: =AC23+AD23+AE23 -> #REF! | AG23: =AF23-X23 -> #REF!
C24: 3 | D24: =#REF! -> #REF! | E24: =#REF! -> #REF! | F24: =#REF! -> #REF! | G24: =#REF! -> #REF! | H24: =#REF! -> #REF! | I24: =#REF! -> #REF! | J24: =#REF! -> #REF! | K24: =#REF! -> #REF! | ... W24: =#REF! -> #REF! | X24: =D24+E24+F24+G24+H24+I24+J24+K24+L24+M24+N24+O24+P24+Q24+R24+S24+T24+U24+V24+W24 -> #REF! | Y24: =#REF! -> #REF! | Z24: =X24+Y24 -> #REF! | AC24: =D24+E24+F24+G24 -> #REF! | AD24: =H24+I24+J24+K24+L24 -> #REF! | AE24: =M24+N24+O24+P24+Q24+R24+S24+T24+U24+V24+W24 -> #REF! | AF24: =AC24+AD24+AE24 -> #REF! | AG24: =AF24-X24 -> #REF!
C25: 4 | D25: =#REF! -> #REF! | E25: =#REF! -> #REF! | F25: =#REF! -> #REF! | G25: =#REF! -> #REF! | H25: =#REF! -> #REF! | I25: =#REF! -> #REF! | J25: =#REF! -> #REF! | K25: =#REF! -> #REF! | ... W25: =#REF! -> #REF! | X25: =D25+E25+F25+G25+H25+I25+J25+K25+L25+M25+N25+O25+P25+Q25+R25+S25+T25+U25+V25+W25 -> #REF! | Y25: =#REF! -> #REF! | Z25: =X25+Y25 -> #REF! | AC25: =D25+E25+F25+G25 -> #REF! | AD25: =H25+I25+J25+K25+L25 -> #REF! | AE25: =M25+N25+O25+P25+Q25+R25+S25+T25+U25+V25+W25 -> #REF! | AF25: =AC25+AD25+AE25 -> #REF! | AG25: =AF25-X25 -> #REF!
B26: 2010 | C26: 1 | D26: =#REF! -> #REF! | E26: =#REF! -> #REF! | F26: =#REF! -> #REF! | G26: =#REF! -> #REF! | H26: =#REF! -> #REF! | I26: =#REF! -> #REF! | J26: =#REF! -> #REF! | K26: =#REF! -> #REF! | ... W26: =#REF! -> #REF! | X26: =D26+E26+F26+G26+H26+I26+J26+K26+L26+M26+N26+O26+P26+Q26+R26+S26+T26+U26+V26+W26 -> #REF! | Y26: =#REF! -> #REF! | Z26: =X26+Y26 -> #REF! | AC26: =D26+E26+F26+G26 -> #REF! | AD26: =H26+I26+J26+K26+L26 -> #REF! | AE26: =M26+N26+O26+P26+Q26+R26+S26+T26+U26+V26+W26 -> #REF! | AF26: =AC26+AD26+AE26 -> #REF! | AG26: =AF26-X26 -> #REF!
C27: 2 | D27: =#REF! -> #REF! | E27: =#REF! -> #REF! | F27: =#REF! -> #REF! | G27: =#REF! -> #REF! | H27: =#REF! -> #REF! | I27: =#REF! -> #REF! | J27: =#REF! -> #REF! | K27: =#REF! -> #REF! | ... W27: =#REF! -> #REF! | X27: =D27+E27+F27+G27+H27+I27+J27+K27+L27+M27+N27+O27+P27+Q27+R27+S27+T27+U27+V27+W27 -> #REF! | Y27: =#REF! -> #REF! | Z27: =X27+Y27 -> #REF! | AC27: =D27+E27+F27+G27 -> #REF! | AD27: =H27+I27+J27+K27+L27 -> #REF! | AE27: =M27+N27+O27+P27+Q27+R27+S27+T27+U27+V27+W27 -> #REF! | AF27: =AC27+AD27+AE27 -> #REF! | AG27: =AF27-X27 -> #REF!
C28: 3 | D28: =#REF! -> #REF! | E28: =#REF! -> #REF! | F28: =#REF! -> #REF! | G28: =#REF! -> #REF! | H28: =#REF! -> #REF! | I28: =#REF! -> #REF! | J28: =#REF! -> #REF! | K28: =#REF! -> #REF! | ... W28: =#REF! -> #REF! | X28: =D28+E28+F28+G28+H28+I28+J28+K28+L28+M28+N28+O28+P28+Q28+R28+S28+T28+U28+V28+W28 -> #REF! | Y28: =#REF! -> #REF! | Z28: =X28+Y28 -> #REF! | AC28: =D28+E28+F28+G28 -> #REF! | AD28: =H28+I28+J28+K28+L28 -> #REF! | AE28: =M28+N28+O28+P28+Q28+R28+S28+T28+U28+V28+W28 -> #REF! | AF28: =AC28+AD28+AE28 -> #REF! | AG28: =AF28-X28 -> #REF!
C29: 4 | D29: =#REF! -> #REF! | E29: =#REF! -> #REF! | F29: =#REF! -> #REF! | G29: =#REF! -> #REF! | H29: =#REF! -> #REF! | I29: =#REF! -> #REF! | J29: =#REF! -> #REF! | K29: =#REF! -> #REF! | ... W29: =#REF! -> #REF! | X29: =D29+E29+F29+G29+H29+I29+J29+K29+L29+M29+N29+O29+P29+Q29+R29+S29+T29+U29+V29+W29 -> #REF! | Y29: =#REF! -> #REF! | Z29: =X29+Y29 -> #REF! | AC29: =D29+E29+F29+G29 -> #REF! | AD29: =H29+I29+J29+K29+L29 -> #REF! | AE29: =M29+N29+O29+P29+Q29+R29+S29+T29+U29+V29+W29 -> #REF! | AF29: =AC29+AD29+AE29 -> #REF! | AG29: =AF29-X29 -> #REF!
B30: 2011 | C30: 1 | D30: =#REF! -> #REF! | E30: =#REF! -> #REF! | F30: =#REF! -> #REF! | G30: =#REF! -> #REF! | H30: =#REF! -> #REF! | I30: =#REF! -> #REF! | J30: =#REF! -> #REF! | K30: =#REF! -> #REF! | ... W30: =#REF! -> #REF! | X30: =D30+E30+F30+G30+H30+I30+J30+K30+L30+M30+N30+O30+P30+Q30+R30+S30+T30+U30+V30+W30 -> #REF! | Y30: =#REF! -> #REF! | Z30: =X30+Y30 -> #REF! | AC30: =D30+E30+F30+G30 -> #REF! | AD30: =H30+I30+J30+K30+L30 -> #REF! | AE30: =M30+N30+O30+P30+Q30+R30+S30+T30+U30+V30+W30 -> #REF! | AF30: =AC30+AD30+AE30 -> #REF! | AG30: =AF30-X30 -> #REF!
C31: 2 | D31: =#REF! -> #REF! | E31: =#REF! -> #REF! | F31: =#REF! -> #REF! | G31: =#REF! -> #REF! | H31: =#REF! -> #REF! | I31: =#REF! -> #REF! | J31: =#REF! -> #REF! | K31: =#REF! -> #REF! | ... W31: =#REF! -> #REF! | X31: =D31+E31+F31+G31+H31+I31+J31+K31+L31+M31+N31+O31+P31+Q31+R31+S31+T31+U31+V31+W31 -> #REF! | Y31: =#REF! -> #REF! | Z31: =X31+Y31 -> #REF! | AC31: =D31+E31+F31+G31 -> #REF! | AD31: =H31+I31+J31+K31+L31 -> #REF! | AE31: =M31+N31+O31+P31+Q31+R31+S31+T31+U31+V31+W31 -> #REF! | AF31: =AC31+AD31+AE31 -> #REF! | AG31: =AF31-X31 -> #REF!
C32: 3* | D32: =#REF! -> #REF! | E32: =#REF! -> #REF! | F32: =#REF! -> #REF! | G32: =#REF! -> #REF! | H32: =#REF! -> #REF! | I32: =#REF! -> #REF! | J32: =#REF! -> #REF! | K32: =#REF! -> #REF! | ... W32: =#REF! -> #REF! | X32: =D32+E32+F32+G32+H32+I32+J32+K32+L32+M32+N32+O32+P32+Q32+R32+S32+T32+U32+V32+W32 -> #REF! | Y32: =#REF! -> #REF! | Z32: =X32+Y32 -> #REF! | AC32: =D32+E32+F32+G32 -> #REF! | AD32: =H32+I32+J32+K32+L32 -> #REF!
C33: 4* | D33: =#REF! -> #REF! | E33: =#REF! -> #REF! | F33: =#REF! -> #REF! | G33: =#REF! -> #REF! | H33: =#REF! -> #REF! | I33: =#REF! -> #REF! | J33: =#REF! -> #REF! | K33: =#REF! -> #REF! | ... W33: =#REF! -> #REF! | X33: =D33+E33+F33+G33+H33+I33+J33+K33+L33+M33+N33+O33+P33+Q33+R33+S33+T33+U33+V33+W33 -> #REF! | Y33: =#REF! -> #REF! | Z33: =X33+Y33 -> #REF!
B34: 2012 | C34: 1* | D34: =#REF! -> #REF! | E34: =#REF! -> #REF! | F34: =#REF! -> #REF! | G34: =#REF! -> #REF! | H34: =#REF! -> #REF! | I34: =#REF! -> #REF! | J34: =#REF! -> #REF! | K34: =#REF! -> #REF! | ... W34: =#REF! -> #REF! | X34: =D34+E34+F34+G34+H34+I34+J34+K34+L34+M34+N34+O34+P34+Q34+R34+S34+T34+U34+V34+W34 -> #REF! | Y34: =#REF! -> #REF! | Z34: =X34+Y34 -> #REF!
B36: * provisional

Sheet T2
B1: Table 2 - Percentage change (quarter-on-quarter) in the quarterly value added by Activity at 2006 constant prices
D2: Agriculture Sector | H2: Industry Sector | M2: Services Sector
B3: Year | C3: Quarter | D3: Crops & Cocoa | E3: Livestock | F3: Forestry | G3: Fishing | H3: Mining and Quarrying | I3: Manufacturing | J3: Electricity | K3: Water & Sewerage | L3: Construction | M3: Trade; Repair Of Vehicles, Household Goods | N3: Hotels And Restaurants | O3: Transport & Storage | P3: Information & Communication | Q3: Financial & Insurance Activities | R3: Real Estate Activities | S3: Business & other Services Activities | T3: Public Administration | U3: Education | V3: Health | W3: Other Personal Service Activities | X3: Total Value Added | Y3: Net Taxes | Z3: GDP at Constant Prices | AC3: Agric | AD3: Ind | AE3: Serv
B4: 2006
B5: 2007 | D5: ='T1'!D5/'T1'!D4*100-100 -> -1.346605 | E5: ='T1'!E5/'T1'!E4*100-100 -> 4.7316467 | F5: ='T1'!F5/'T1'!F4*100-100 -> -4.0926214 | G5: ='T1'!G5/'T1'!G4*100-100 -> -7.2472487 | H5: ='T1'!H5/'T1'!H4*100-100 -> 6.8620818 | I5: ='T1'!I5/'T1'!I4*100-100 -> -1.2158585 | J5: ='T1'!J5/'T1'!J4*100-100 -> -17.212572 | K5: ='T1'!K5/'T1'!K4*100-100 -> 1.161077 | ... Z5: ='T1'!Z5/'T1'!Z4*100-100 -> 6.459768
B6: 2008 | D6: ='T1'!D6/'T1'!D5*100-100 -> 8.6 | E6: ='T1'!E6/'T1'!E5*100-100 -> 5.1039655 | F6: ='T1'!F6/'T1'!F5*100-100 -> -3.3201314 | G6: ='T1'!G6/'T1'!G5*100-100 -> 17.380777 | H6: ='T1'!H6/'T1'!H5*100-100 -> 2.4193735 | I6: ='T1'!I6/'T1'!I5*100-100 -> 3.7004754 | J6: ='T1'!J6/'T1'!J5*100-100 -> 19.423493 | K6: ='T1'!K6/'T1'!K5*100-100 -> 0.84657122 | ... Z6: ='T1'!Z6/'T1'!Z5*100-100 -> 8.430638
B7: 2009 | D7: ='T1'!D7/'T1'!D6*100-100 -> 10.209647 | E7: ='T1'!E7/'T1'!E6*100-100 -> 4.3665196 | F7: ='T1'!F7/'T1'!F6*100-100 -> 0.72021485 | G7: ='T1'!G7/'T1'!G6*100-100 -> -5.711463 | H7: ='T1'!H7/'T1'!H6*100-100 -> 6.751655 | I7: ='T1'!I7/'T1'!I6*100-100 -> -1.3056694 | J7: ='T1'!J7/'T1'!J6*100-100 -> 7.5043898 | K7: ='T1'!K7/'T1'!K6*100-100 -> 7.6501012 | ... Z7: ='T1'!Z7/'T1'!Z6*100-100 -> 3.9936182
B8: 2010 | D8: ='T1'!D8/'T1'!D7*100-100 -> 5.0000539 | E8: ='T1'!E8/'T1'!E7*100-100 -> 4.6493195 | F8: ='T1'!F8/'T1'!F7*100-100 -> 10.071289 | G8: ='T1'!G8/'T1'!G7*100-100 -> 1.4907404 | H8: ='T1'!H8/'T1'!H7*100-100 -> 7.642783 | I8: ='T1'!I8/'T1'!I7*100-100 -> 7.6004356 | J8: ='T1'!J8/'T1'!J7*100-100 -> 12.260229 | K8: ='T1'!K8/'T1'!K7*100-100 -> 5.2637697 | ... Z8: ='T1'!Z8/'T1'!Z7*100-100 -> 7.7171007
B10: 2006 | C10: 1 | AC10: =D10+E10+F10+G10 -> 0 | AD10: =H10+I10+J10+K10+L10 -> 0 | AE10: =M10+N10+O10+P10+Q10+R10+S10+T10+U10+V10+W10 -> 0
C11: 2 | D11: ='qly growth rates'!C6 -> #REF! | E11: ='qly growth rates'!D6 -> #REF! | F11: ='qly growth rates'!E6 -> #REF! | G11: ='qly growth rates'!F6 -> #REF! | H11: ='qly growth rates'!G6 -> #REF! | I11: ='qly growth rates'!H6 -> #REF! | J11: ='qly growth rates'!I6 -> #REF! | K11: ='qly growth rates'!J6 -> #REF! | ... Z11: ='qly growth rates'!Y6 -> #REF! | AC11: ='T1'!AC11/'T1'!AC10*100-100 -> #REF! | AD11: ='T1'!AD11/'T1'!AD10*100-100 -> #REF! | AE11: ='T1'!AE11/'T1'!AE10*100-100 -> #REF!
C12: 3 | D12: ='qly growth rates'!C7 -> #REF! | E12: ='qly growth rates'!D7 -> #REF! | F12: ='qly growth rates'!E7 -> #REF! | G12: ='qly growth rates'!F7 -> #REF! | H12: ='qly growth rates'!G7 -> #REF! | I12: ='qly growth rates'!H7 -> #REF! | J12: ='qly growth rates'!I7 -> #REF! | K12: ='qly growth rates'!J7 -> #REF! | ... Z12: ='qly growth rates'!Y7 -> #REF! | AC12: ='T1'!AC12/'T1'!AC11*100-100 -> #REF! | AD12: ='T1'!AD12/'T1'!AD11*100-100 -> #REF! | AE12: ='T1'!AE12/'T1'!AE11*100-100 -> #REF!
C13: 4 | D13: ='qly growth rates'!C8 -> #REF! | E13: ='qly growth rates'!D8 -> #REF! | F13: ='qly growth rates'!E8 -> #REF! | G13: ='qly growth rates'!F8 -> #REF! | H13: ='qly growth rates'!G8 -> #REF! | I13: ='qly growth rates'!H8 -> #REF! | J13: ='qly growth rates'!I8 -> #REF! | K13: ='qly growth rates'!J8 -> #REF! | ... Z13: ='qly growth rates'!Y8 -> #REF! | AC13: ='T1'!AC13/'T1'!AC12*100-100 -> #REF! | AD13: ='T1'!AD13/'T1'!AD12*100-100 -> #REF! | AE13: ='T1'!AE13/'T1'!AE12*100-100 -> #REF!
B14: 2007 | C14: 1 | D14: ='qly growth rates'!C9 -> #REF! | E14: ='qly growth rates'!D9 -> #REF! | F14: ='qly growth rates'!E9 -> #REF! | G14: ='qly growth rates'!F9 -> #REF! | H14: ='qly growth rates'!G9 -> #REF! | I14: ='qly growth rates'!H9 -> #REF! | J14: ='qly growth rates'!I9 -> #REF! | K14: ='qly growth rates'!J9 -> #REF! | ... Z14: ='qly growth rates'!Y9 -> #REF! | AC14: ='T1'!AC14/'T1'!AC13*100-100 -> #REF! | AD14: ='T1'!AD14/'T1'!AD13*100-100 -> #REF! | AE14: ='T1'!AE14/'T1'!AE13*100-100 -> #REF!
C15: 2 | D15: ='qly growth rates'!C10 -> #REF! | E15: ='qly growth rates'!D10 -> #REF! | F15: ='qly growth rates'!E10 -> #REF! | G15: ='qly growth rates'!F10 -> #REF! | H15: ='qly growth rates'!G10 -> #REF! | I15: ='qly growth rates'!H10 -> #REF! | J15: ='qly growth rates'!I10 -> #REF! | K15: ='qly growth rates'!J10 -> #REF! | ... Z15: ='qly growth rates'!Y10 -> #REF! | AC15: ='T1'!AC15/'T1'!AC14*100-100 -> #REF! | AD15: ='T1'!AD15/'T1'!AD14*100-100 -> #REF! | AE15: ='T1'!AE15/'T1'!AE14*100-100 -> #REF!
C16: 3 | D16: ='qly growth rates'!C11 -> #REF! | E16: ='qly growth rates'!D11 -> #REF! | F16: ='qly growth rates'!E11 -> #REF! | G16: ='qly growth rates'!F11 -> #REF! | H16: ='qly growth rates'!G11 -> #REF! | I16: ='qly growth rates'!H11 -> #REF! | J16: ='qly growth rates'!I11 -> #REF! | K16: ='qly growth rates'!J11 -> #REF! | ... Z16: ='qly growth rates'!Y11 -> #REF! | AC16: ='T1'!AC16/'T1'!AC15*100-100 -> #REF! | AD16: ='T1'!AD16/'T1'!AD15*100-100 -> #REF! | AE16: ='T1'!AE16/'T1'!AE15*100-100 -> #REF!
C17: 4 | D17: ='qly growth rates'!C12 -> #REF! | E17: ='qly growth rates'!D12 -> #REF! | F17: ='qly growth rates'!E12 -> #REF! | G17: ='qly growth rates'!F12 -> #REF! | H17: ='qly growth rates'!G12 -> #REF! | I17: ='qly growth rates'!H12 -> #REF! | J17: ='qly growth rates'!I12 -> #REF! | K17: ='qly growth rates'!J12 -> #REF! | ... Z17: ='qly growth rates'!Y12 -> #REF! | AC17: ='T1'!AC17/'T1'!AC16*100-100 -> #REF! | AD17: ='T1'!AD17/'T1'!AD16*100-100 -> #REF! | AE17: ='T1'!AE17/'T1'!AE16*100-100 -> #REF!
B18: 2008 | C18: 1 | D18: ='qly growth rates'!C13 -> #REF! | E18: ='qly growth rates'!D13 -> #REF! | F18: ='qly growth rates'!E13 -> #REF! | G18: ='qly growth rates'!F13 -> #REF! | H18: ='qly growth rates'!G13 -> #REF! | I18: ='qly growth rates'!H13 -> #REF! | J18: ='qly growth rates'!I13 -> #REF! | K18: ='qly growth rates'!J13 -> #REF! | ... Z18: ='qly growth rates'!Y13 -> #REF! | AC18: ='T1'!AC18/'T1'!AC17*100-100 -> #REF! | AD18: ='T1'!AD18/'T1'!AD17*100-100 -> #REF! | AE18: ='T1'!AE18/'T1'!AE17*100-100 -> #REF!
C19: 2 | D19: ='qly growth rates'!C14 -> #REF! | E19: ='qly growth rates'!D14 -> #REF! | F19: ='qly growth rates'!E14 -> #REF! | G19: ='qly growth rates'!F14 -> #REF! | H19: ='qly growth rates'!G14 -> #REF! | I19: ='qly growth rates'!H14 -> #REF! | J19: ='qly growth rates'!I14 -> #REF! | K19: ='qly growth rates'!J14 -> #REF! | ... Z19: ='qly growth rates'!Y14 -> #REF! | AC19: ='T1'!AC19/'T1'!AC18*100-100 -> #REF! | AD19: ='T1'!AD19/'T1'!AD18*100-100 -> #REF! | AE19: ='T1'!AE19/'T1'!AE18*100-100 -> #REF!
C20: 3 | D20: ='qly growth rates'!C15 -> #REF! | E20: ='qly growth rates'!D15 -> #REF! | F20: ='qly growth rates'!E15 -> #REF! | G20: ='qly growth rates'!F15 -> #REF! | H20: ='qly growth rates'!G15 -> #REF! | I20: ='qly growth rates'!H15 -> #REF! | J20: ='qly growth rates'!I15 -> #REF! | K20: ='qly growth rates'!J15 -> #REF! | ... Z20: ='qly growth rates'!Y15 -> #REF! | AC20: ='T1'!AC20/'T1'!AC19*100-100 -> #REF! | AD20: ='T1'!AD20/'T1'!AD19*100-100 -> #REF! | AE20: ='T1'!AE20/'T1'!AE19*100-100 -> #REF!
C21: 4 | D21: ='qly growth rates'!C16 -> #REF! | E21: ='qly growth rates'!D16 -> #REF! | F21: ='qly growth rates'!E16 -> #REF! | G21: ='qly growth rates'!F16 -> #REF! | H21: ='qly growth rates'!G16 -> #REF! | I21: ='qly growth rates'!H16 -> #REF! | J21: ='qly growth rates'!I16 -> #REF! | K21: ='qly growth rates'!J16 -> #REF! | ... Z21: ='qly growth rates'!Y16 -> #REF! | AC21: ='T1'!AC21/'T1'!AC20*100-100 -> #REF! | AD21: ='T1'!AD21/'T1'!AD20*100-100 -> #REF! | AE21: ='T1'!AE21/'T1'!AE20*100-100 -> #REF!
B22: 2009 | C22: 1 | D22: ='qly growth rates'!C17 -> #REF! | E22: ='qly growth rates'!D17 -> #REF! | F22: ='qly growth rates'!E17 -> #REF! | G22: ='qly growth rates'!F17 -> #REF! | H22: ='qly growth rates'!G17 -> #REF! | I22: ='qly growth rates'!H17 -> #REF! | J22: ='qly growth rates'!I17 -> #REF! | K22: ='qly growth rates'!J17 -> #REF! | ... Z22: ='qly growth rates'!Y17 -> #REF! | AC22: ='T1'!AC22/'T1'!AC21*100-100 -> #REF! | AD22: ='T1'!AD22/'T1'!AD21*100-100 -> #REF! | AE22: ='T1'!AE22/'T1'!AE21*100-100 -> #REF!
C23: 2 | D23: ='qly growth rates'!C18 -> #REF! | E23: ='qly growth rates'!D18 -> #REF! | F23: ='qly growth rates'!E18 -> #REF! | G23: ='qly growth rates'!F18 -> #REF! | H23: ='qly growth rates'!G18 -> #REF! | I23: ='qly growth rates'!H18 -> #REF! | J23: ='qly growth rates'!I18 -> #REF! | K23: ='qly growth rates'!J18 -> #REF! | ... Z23: ='qly growth rates'!Y18 -> #REF! | AC23: ='T1'!AC23/'T1'!AC22*100-100 -> #REF! | AD23: ='T1'!AD23/'T1'!AD22*100-100 -> #REF! | AE23: ='T1'!AE23/'T1'!AE22*100-100 -> #REF!
C24: 3 | D24: ='qly growth rates'!C19 -> #REF! | E24: ='qly growth rates'!D19 -> #REF! | F24: ='qly growth rates'!E19 -> #REF! | G24: ='qly growth rates'!F19 -> #REF! | H24: ='qly growth rates'!G19 -> #REF! | I24: ='qly growth rates'!H19 -> #REF! | J24: ='qly growth rates'!I19 -> #REF! | K24: ='qly growth rates'!J19 -> #REF! | ... Z24: ='qly growth rates'!Y19 -> #REF! | AC24: ='T1'!AC24/'T1'!AC23*100-100 -> #REF! | AD24: ='T1'!AD24/'T1'!AD23*100-100 -> #REF! | AE24: ='T1'!AE24/'T1'!AE23*100-100 -> #REF!
C25: 4 | D25: ='qly growth rates'!C20 -> #REF! | E25: ='qly growth rates'!D20 -> #REF! | F25: ='qly growth rates'!E20 -> #REF! | G25: ='qly growth rates'!F20 -> #REF! | H25: ='qly growth rates'!G20 -> #REF! | I25: ='qly growth rates'!H20 -> #REF! | J25: ='qly growth rates'!I20 -> #REF! | K25: ='qly growth rates'!J20 -> #REF! | ... Z25: ='qly growth rates'!Y20 -> #REF! | AC25: ='T1'!AC25/'T1'!AC24*100-100 -> #REF! | AD25: ='T1'!AD25/'T1'!AD24*100-100 -> #REF! | AE25: ='T1'!AE25/'T1'!AE24*100-100 -> #REF!
B26: 2010 | C26: 1 | D26: ='qly growth rates'!C21 -> #REF! | E26: ='qly growth rates'!D21 -> #REF! | F26: ='qly growth rates'!E21 -> #REF! | G26: ='qly growth rates'!F21 -> #REF! | H26: ='qly growth rates'!G21 -> #REF! | I26: ='qly growth rates'!H21 -> #REF! | J26: ='qly growth rates'!I21 -> #REF! | K26: ='qly growth rates'!J21 -> #REF! | ... Z26: ='qly growth rates'!Y21 -> #REF! | AC26: ='T1'!AC26/'T1'!AC25*100-100 -> #REF! | AD26: ='T1'!AD26/'T1'!AD25*100-100 -> #REF! | AE26: ='T1'!AE26/'T1'!AE25*100-100 -> #REF!
C27: 2 | D27: ='qly growth rates'!C22 -> #REF! | E27: ='qly growth rates'!D22 -> #REF! | F27: ='qly growth rates'!E22 -> #REF! | G27: ='qly growth rates'!F22 -> #REF! | H27: ='qly growth rates'!G22 -> #REF! | I27: ='qly growth rates'!H22 -> #REF! | J27: ='qly growth rates'!I22 -> #REF! | K27: ='qly growth rates'!J22 -> #REF! | ... Z27: ='qly growth rates'!Y22 -> #REF! | AC27: ='T1'!AC27/'T1'!AC26*100-100 -> #REF! | AD27: ='T1'!AD27/'T1'!AD26*100-100 -> #REF! | AE27: ='T1'!AE27/'T1'!AE26*100-100 -> #REF!
C28: 3 | D28: ='qly growth rates'!C23 -> #REF! | E28: ='qly growth rates'!D23 -> #REF! | F28: ='qly growth rates'!E23 -> #REF! | G28: ='qly growth rates'!F23 -> #REF! | H28: ='qly growth rates'!G23 -> #REF! | I28: ='qly growth rates'!H23 -> #REF! | J28: ='qly growth rates'!I23 -> #REF! | K28: ='qly growth rates'!J23 -> #REF! | ... Z28: ='qly growth rates'!Y23 -> #REF! | AC28: ='T1'!AC28/'T1'!AC27*100-100 -> #REF! | AD28: ='T1'!AD28/'T1'!AD27*100-100 -> #REF! | AE28: ='T1'!AE28/'T1'!AE27*100-100 -> #REF!
C29: 4 | D29: ='qly growth rates'!C24 -> #REF! | E29: ='qly growth rates'!D24 -> #REF! | F29: ='qly growth rates'!E24 -> #REF! | G29: ='qly growth rates'!F24 -> #REF! | H29: ='qly growth rates'!G24 -> #REF! | I29: ='qly growth rates'!H24 -> #REF! | J29: ='qly growth rates'!I24 -> #REF! | K29: ='qly growth rates'!J24 -> #REF! | ... Z29: ='qly growth rates'!Y24 -> #REF! | AC29: ='T1'!AC29/'T1'!AC28*100-100 -> #REF! | AD29: ='T1'!AD29/'T1'!AD28*100-100 -> #REF! | AE29: ='T1'!AE29/'T1'!AE28*100-100 -> #REF!
B30: 2011 | C30: 1 | D30: ='qly growth rates'!C25 -> #REF! | E30: ='qly growth rates'!D25 -> #REF! | F30: ='qly growth rates'!E25 -> #REF! | G30: ='qly growth rates'!F25 -> #REF! | H30: ='qly growth rates'!G25 -> #REF! | I30: ='qly growth rates'!H25 -> #REF! | J30: ='qly growth rates'!I25 -> #REF! | K30: ='qly growth rates'!J25 -> #REF! | ... Z30: ='qly growth rates'!Y25 -> #REF! | AC30: ='T1'!AC30/'T1'!AC29*100-100 -> #REF! | AD30: ='T1'!AD30/'T1'!AD29*100-100 -> #REF! | AE30: ='T1'!AE30/'T1'!AE29*100-100 -> #REF!
C31: 2 | D31: ='qly growth rates'!C26 -> #REF! | E31: ='qly growth rates'!D26 -> #REF! | F31: ='qly growth rates'!E26 -> #REF! | G31: ='qly growth rates'!F26 -> #REF! | H31: ='qly growth rates'!G26 -> #REF! | I31: ='qly growth rates'!H26 -> #REF! | J31: ='qly growth rates'!I26 -> #REF! | K31: ='qly growth rates'!J26 -> #REF! | ... Z31: ='qly growth rates'!Y26 -> #REF! | AC31: ='T1'!AC31/'T1'!AC30*100-100 -> #REF! | AD31: ='T1'!AD31/'T1'!AD30*100-100 -> #REF! | AE31: ='T1'!AE31/'T1'!AE30*100-100 -> #REF!
C32: 3* | D32: ='qly growth rates'!C27 -> #REF! | E32: ='qly growth rates'!D27 -> #REF! | F32: ='qly growth rates'!E27 -> #REF! | G32: ='qly growth rates'!F27 -> #REF! | H32: ='qly growth rates'!G27 -> #REF! | I32: ='qly growth rates'!H27 -> #REF! | J32: ='qly growth rates'!I27 -> #REF! | K32: ='qly growth rates'!J27 -> #REF! | ... Z32: ='qly growth rates'!Y27 -> #REF! | AC32: ='T1'!AC32/'T1'!AC31*100-100 -> #REF! | AD32: ='T1'!AD32/'T1'!AD31*100-100 -> #REF! | AE32: ='T1'!AE32/'T1'!AE31*100-100 -> #REF!
C33: 4* | D33: ='qly growth rates'!C28 -> 0 | E33: ='qly growth rates'!D28 -> 0 | F33: ='qly growth rates'!E28 -> 0 | G33: ='qly growth rates'!F28 -> 0 | H33: ='qly growth rates'!G28 -> 0 | I33: ='qly growth rates'!H28 -> 0 | J33: ='qly growth rates'!I28 -> 0 | K33: ='qly growth rates'!J28 -> 0 | ... Z33: ='qly growth rates'!Y28 -> 0 | AC33: ='T1'!AC33/'T1'!AC32*100-100 -> #REF! | AD33: ='T1'!AD33/'T1'!AD32*100-100 -> #REF! | AE33: ='T1'!AE33/'T1'!AE32*100-100 -> #DIV/0!
B34: 2012 | C34: 1* | D34: ='qly growth rates'!C29 -> 0 | E34: ='qly growth rates'!D29 -> 0 | F34: ='qly growth rates'!E29 -> 0 | G34: ='qly growth rates'!F29 -> 0 | H34: ='qly growth rates'!G29 -> 0 | I34: ='qly growth rates'!H29 -> 0 | J34: ='qly growth rates'!I29 -> 0 | K34: ='qly growth rates'!J29 -> 0 | ... Z34: ='qly growth rates'!Y29 -> 0
B36: * provisional

Sheet T1 (2)
B1: Table 1 - Quarterly Value Added by Activity and Gross Domestic Product at Constant 2006 Prices (GHc Million)
D2: Agriculture Sector | I2: Industry Sector | O2: Services Sector | AA2: Total Value Added at Basis Prices
B3: Year | C3: Quarter | D3: Crops & Cocoa | E3: Livestock | F3: Forestry | G3: Fishing | H3: Total Value Added | I3: Mining and Quarrying | J3: Manufacturing | K3: Electricity | L3: Water & Sewerage | M3: Construction | N3: Total Value Added | O3: Trade; Repair Of Vehicles, Household Goods | P3: Hotels And Restaurants | Q3: Transport & Storage | R3: Information & Communication | S3: Financial & Insurance Activities | T3: Real Estate Activities | U3: Business & other Services Activities | V3: Public Administration | W3: Education | X3: Health | Y3: Other Personal Service Activities | Z3: Total Value Added
D4: 1 | E4: 2 | F4: 3 | G4: 4 | H4: 5=1+2+3+4 | I4: 6 | J4: 7 | K4: 8 | L4: 9 | M4: 10 | N4: 11=6+...+10 | O4: 11 | P4: 12 | Q4: 13 | R4: 14 | S4: 15 | T4: 16 | U4: 17 | V4: 18 | W4: 19 | X4: 20 | Y4: 21 | Z4: 22=11+...21 | AA4: 23=5+11+23
AG5: =D3 -> Crops & Cocoa | AH5: =E3 -> Livestock | AI5: =F3 -> Forestry | AJ5: =G3 -> Fishing | AL5: =I3 -> Mining and Quarrying | AM5: =J3 -> Manufacturing | AN5: =K3 -> Electricity | AO5: =L3 -> Water & Sewerage | AP5: =M3 -> Construction | AR5: =O3 -> Trade; Repair Of Vehicles, Household Goods | AS5: =P3 -> Hotels And Restaurants | AT5: =Q3 -> Transport & Storage | AU5: =R3 -> Information & Communication | AV5: =S3 -> Financial & Insurance Activities | AW5: =T3 -> Real Estate Activities | AX5: =U3 -> Business & other Services Activities | AY5: =V3 -> Public Administration | ... BB5: =Y3 -> Other Personal Service Activities
B6: 2006 | D6: 3793.682 | E6: 437.09725 | F6: 736.00309 | G6: 448.25153 | H6: =SUM(D6:G6) -> 5415.0338 | I6: 497.4452 | J6: 1823.4833 | K6: 142.71912 | L6: 224.36136 | M6: 1016.2744 | N6: =SUM(I6:M6) -> 3704.2834 | O6: 1140.6992 | P6: 894.08203 | Q6: 2357.2217 | R6: 483.03723 | S6: 472.8561 | T6: 391.4 | U6: 522.52707 | V6: 862.13807 | W6: 654.95995 | X6: 249.83921 | Y6: 661.61553 | Z6: =SUM(O6:Y6) -> 8690.3761 | AA6: =D6+E6+F6+G6+I6+J6+K6+L6+M6+O6+P6+Q6+R6+S6+T6+U6+V6+W6+X6+Y6 -> 17809.693 | AF6: 06q1 | AG6: =D12 -> #REF! | AH6: =E12 -> #REF! | AI6: =F12 -> #REF! | AJ6: =G12 -> #REF! | AL6: =I12 -> #REF! | AM6: =J12 -> #REF! | AN6: =K12 -> #REF! | AO6: =L12 -> #REF! | AP6: =M12 -> #REF! | AR6: =O12 -> #REF! | AS6: =P12 -> #REF! | AT6: =Q12 -> #REF! | AU6: =R12 -> #REF! | AV6: =S12 -> #REF! | AW6: =T12 -> #REF! | AX6: =U12 -> #REF! | AY6: =V12 -> #REF! | ... BB6: =Y12 -> #REF!
B7: 2007 | D7: 3742.596 | E7: 457.77915 | F7: 705.88127 | G7: 415.76563 | H7: =SUM(D7:G7) -> 5322.0221 | I7: 531.5803 | J7: 1801.3123 | K7: 118.15348 | L7: 226.96637 | M7: 1251.5619 | N7: =SUM(I7:M7) -> 3929.5743 | O7: 1202.6217 | P7: 916.59233 | Q7: 2573.4037 | R7: 502.84176 | S7: 559.76897 | T7: 400.7936 | U7: 542.72237 | V7: 959.55967 | W7: 720.45595 | X7: 259.27272 | Y7: 720.31678 | Z7: =SUM(O7:Y7) -> 9358.3495 | AA7: =D7+E7+F7+G7+I7+J7+K7+L7+M7+O7+P7+Q7+R7+S7+T7+U7+V7+W7+X7+Y7 -> 18609.946 | AF7: 06q2 | AG7: =D13 -> #REF! | AH7: =E13 -> #REF! | AI7: =F13 -> #REF! | AJ7: =G13 -> #REF! | AL7: =I13 -> #REF! | AM7: =J13 -> #REF! | AN7: =K13 -> #REF! | AO7: =L13 -> #REF! | AP7: =M13 -> #REF! | AR7: =O13 -> #REF! | AS7: =P13 -> #REF! | AT7: =Q13 -> #REF! | AU7: =R13 -> #REF! | AV7: =S13 -> #REF! | AW7: =T13 -> #REF! | AX7: =U13 -> #REF! | AY7: =V13 -> #REF! | ... BB7: =Y13 -> #REF!
B8: 2008 | D8: 4064.4593 | E8: 481.14404 | F8: 682.44508 | G8: 488.02892 | H8: =SUM(D8:G8) -> 5716.0774 | I8: 544.44121 | J8: 1867.9694 | K8: 141.10302 | L8: 228.8878 | M8: 1739.4644 | N8: =SUM(I8:M8) -> 4521.8658 | O8: 1316.9257 | P8: 999.77813 | Q8: 2671.91 | R8: 600.8959 | S8: 620.12127 | T8: 410.41265 | U8: 532.78696 | V8: 1081.751 | W8: 814.29858 | X8: 270.78237 | Y8: 786.30765 | Z8: =SUM(O8:Y8) -> 10105.97 | AA8: =D8+E8+F8+G8+I8+J8+K8+L8+M8+O8+P8+Q8+R8+S8+T8+U8+V8+W8+X8+Y8 -> 20343.913 | AF8: 06q3 | AG8: =D14 -> #REF! | AH8: =E14 -> #REF! | AI8: =F14 -> #REF! | AJ8: =G14 -> #REF! | AL8: =I14 -> #REF! | AM8: =J14 -> #REF! | AN8: =K14 -> #REF! | AO8: =L14 -> #REF! | AP8: =M14 -> #REF! | AR8: =O14 -> #REF! | AS8: =P14 -> #REF! | AT8: =Q14 -> #REF! | AU8: =R14 -> #REF! | AV8: =S14 -> #REF! | AW8: =T14 -> #REF! | AX8: =U14 -> #REF! | AY8: =V14 -> #REF! | ... BB8: =Y14 -> #REF!
B9: 2009 | D9: 4479.4263 | E9: 502.15329 | F9: 687.36015 | G9: 460.15533 | H9: =SUM(D9:G9) -> 6129.095 | I9: 581.2 | J9: 1843.5799 | K9: 151.69194 | L9: 246.39795 | M9: 1901.8527 | N9: =SUM(I9:M9) -> 4724.7225 | O9: 1387.931 | P9: 962.00084 | Q9: 2790.1363 | R9: 624.16472 | S9: 677.93817 | T9: 420.26255 | U9: 524.52844 | V9: 1208.1799 | W9: 914.89016 | X9: 311.81225 | Y9: 845.05032 | Z9: =SUM(O9:Y9) -> 10666.895 | AA9: =D9+E9+F9+G9+I9+J9+K9+L9+M9+O9+P9+Q9+R9+S9+T9+U9+V9+W9+X9+Y9 -> 21520.712 | AF9: 06q4 | AG9: =D15 -> #REF! | AH9: =E15 -> #REF! | AI9: =F15 -> #REF! | AJ9: =G15 -> #REF! | AL9: =I15 -> #REF! | AM9: =J15 -> #REF! | AN9: =K15 -> #REF! | AO9: =L15 -> #REF! | AP9: =M15 -> #REF! | AR9: =O15 -> #REF! | AS9: =P15 -> #REF! | AT9: =Q15 -> #REF! | AU9: =R15 -> #REF! | AV9: =S15 -> #REF! | AW9: =T15 -> #REF! | AX9: =U15 -> #REF! | AY9: =V15 -> #REF! | ... BB9: =Y15 -> #REF!
B10: 2010 | D10: 4703.4 | E10: 525.5 | F10: 756.58618 | G10: 467.01505 | H10: =SUM(D10:G10) -> 6452.5012 | I10: 625.61986 | J10: 1983.7 | K10: 170.28972 | L10: 259.36777 | M10: 1949.3991 | N10: =SUM(I10:M10) -> 4988.3764 | O10: 1573.0945 | P10: 987.85721 | Q10: 3014.308 | R10: 776.90602 | S10: 791.49056 | T10: 430.34885 | U10: 645.7 | V10: 1248.9614 | W10: 963.21808 | X10: 346.86159 | Y10: 935.5 | Z10: =SUM(O10:Y10) -> 11714.246 | AA10: =D10+E10+F10+G10+I10+J10+K10+L10+M10+O10+P10+Q10+R10+S10+T10+U10+V10+W10+X10+Y10 -> 23155.124 | AF10: 07q1 | AG10: =D16 -> #REF! | AH10: =E16 -> #REF! | AI10: =F16 -> #REF! | AJ10: =G16 -> #REF! | AL10: =I16 -> #REF! | AM10: =J16 -> #REF! | AN10: =K16 -> #REF! | AO10: =L16 -> #REF! | AP10: =M16 -> #REF! | AR10: =O16 -> #REF! | AS10: =P16 -> #REF! | AT10: =Q16 -> #REF! | AU10: =R16 -> #REF! | AV10: =S16 -> #REF! | AW10: =T16 -> #REF! | AX10: =U16 -> #REF! | AY10: =V16 -> #REF! | ... BB10: =Y16 -> #REF!
B11: 2011 | H11: =SUM(D11:G11) -> 0 | N11: =SUM(I11:M11) -> 0 | Z11: =SUM(O11:Y11) -> 0 | AA11: =D11+E11+F11+G11+I11+J11+K11+L11+M11+O11+P11+Q11+R11+S11+T11+U11+V11+W11+X11+Y11 -> 0 | AF11: 07q2 | AG11: =D17 -> #REF! | AH11: =E17 -> #REF! | AI11: =F17 -> #REF! | AJ11: =G17 -> #REF! | AL11: =I17 -> #REF! | AM11: =J17 -> #REF! | AN11: =K17 -> #REF! | AO11: =L17 -> #REF! | AP11: =M17 -> #REF! | AR11: =O17 -> #REF! | AS11: =P17 -> #REF! | AT11: =Q17 -> #REF! | AU11: =R17 -> #REF! | AV11: =S17 -> #REF! | AW11: =T17 -> #REF! | AX11: =U17 -> #REF! | AY11: =V17 -> #REF! | ... BB11: =Y17 -> #REF!
B12: 2006 | C12: Q1 | D12: =#REF! -> #REF! | E12: =#REF! -> #REF! | F12: =#REF! -> #REF! | G12: =#REF! -> #REF! | H12: =SUM(D12:G12) -> #REF! | I12: =#REF! -> #REF! | J12: =#REF! -> #REF! | K12: =#REF! -> #REF! | L12: =#REF! -> #REF! | M12: =#REF! -> #REF! | N12: =SUM(I12:M12) -> #REF! | O12: =#REF! -> #REF! | P12: =#REF! -> #REF! | Q12: =#REF! -> #REF! | R12: =#REF! -> #REF! | S12: =#REF! -> #REF! | T12: =#REF! -> #REF! | U12: =#REF! -> #REF! | V12: =#REF! -> #REF! | ... Y12: =#REF! -> #REF! | Z12: =SUM(O12:Y12) -> #REF! | AA12: =D12+E12+F12+G12+I12+J12+K12+L12+M12+O12+P12+Q12+R12+S12+T12+U12+V12+W12+X12+Y12 -> #REF! | AF12: 07q3 | AG12: =D18 -> #REF! | AH12: =E18 -> #REF! | AI12: =F18 -> #REF! | AJ12: =G18 -> #REF! | AL12: =I18 -> #REF! | AM12: =J18 -> #REF! | AN12: =K18 -> #REF! | AO12: =L18 -> #REF! | AP12: =M18 -> #REF! | AR12: =O18 -> #REF! | AS12: =P18 -> #REF! | AT12: =Q18 -> #REF! | AU12: =R18 -> #REF! | AV12: =S18 -> #REF! | AW12: =T18 -> #REF! | AX12: =U18 -> #REF! | AY12: =V18 -> #REF! | ... BB12: =Y18 -> #REF!
C13: Q2 | D13: =#REF! -> #REF! | E13: =#REF! -> #REF! | F13: =#REF! -> #REF! | G13: =#REF! -> #REF! | H13: =SUM(D13:G13) -> #REF! | I13: =#REF! -> #REF! | J13: =#REF! -> #REF! | K13: =#REF! -> #REF! | L13: =#REF! -> #REF! | M13: =#REF! -> #REF! | N13: =SUM(I13:M13) -> #REF! | O13: =#REF! -> #REF! | P13: =#REF! -> #REF! | Q13: =#REF! -> #REF! | R13: =#REF! -> #REF! | S13: =#REF! -> #REF! | T13: =#REF! -> #REF! | U13: =#REF! -> #REF! | V13: =#REF! -> #REF! | ... Y13: =#REF! -> #REF! | Z13: =SUM(O13:Y13) -> #REF! | AA13: =D13+E13+F13+G13+I13+J13+K13+L13+M13+O13+P13+Q13+R13+S13+T13+U13+V13+W13+X13+Y13 -> #REF! | AF13: 07q4 | AG13: =D19 -> #REF! | AH13: =E19 -> #REF! | AI13: =F19 -> #REF! | AJ13: =G19 -> #REF! | AL13: =I19 -> #REF! | AM13: =J19 -> #REF! | AN13: =K19 -> #REF! | AO13: =L19 -> #REF! | AP13: =M19 -> #REF! | AR13: =O19 -> #REF! | AS13: =P19 -> #REF! | AT13: =Q19 -> #REF! | AU13: =R19 -> #REF! | AV13: =S19 -> #REF! | AW13: =T19 -> #REF! | AX13: =U19 -> #REF! | AY13: =V19 -> #REF! | ... BB13: =Y19 -> #REF!
C14: Q3 | D14: =#REF! -> #REF! | E14: =#REF! -> #REF! | F14: =#REF! -> #REF! | G14: =#REF! -> #REF! | H14: =SUM(D14:G14) -> #REF! | I14: =#REF! -> #REF! | J14: =#REF! -> #REF! | K14: =#REF! -> #REF! | L14: =#REF! -> #REF! | M14: =#REF! -> #REF! | N14: =SUM(I14:M14) -> #REF! | O14: =#REF! -> #REF! | P14: =#REF! -> #REF! | Q14: =#REF! -> #REF! | R14: =#REF! -> #REF! | S14: =#REF! -> #REF! | T14: =#REF! -> #REF! | U14: =#REF! -> #REF! | V14: =#REF! -> #REF! | ... Y14: =#REF! -> #REF! | Z14: =SUM(O14:Y14) -> #REF! | AA14: =D14+E14+F14+G14+I14+J14+K14+L14+M14+O14+P14+Q14+R14+S14+T14+U14+V14+W14+X14+Y14 -> #REF! | AF14: 08q1 | AG14: =D20 -> #REF! | AH14: =E20 -> #REF! | AI14: =F20 -> #REF! | AJ14: =G20 -> #REF! | AL14: =I20 -> #REF! | AM14: =J20 -> #REF! | AN14: =K20 -> #REF! | AO14: =L20 -> #REF! | AP14: =M20 -> #REF! | AR14: =O20 -> #REF! | AS14: =P20 -> #REF! | AT14: =Q20 -> #REF! | AU14: =R20 -> #REF! | AV14: =S20 -> #REF! | AW14: =T20 -> #REF! | AX14: =U20 -> #REF! | AY14: =V20 -> #REF! | ... BB14: =Y20 -> #REF!
C15: Q4 | D15: =#REF! -> #REF! | E15: =#REF! -> #REF! | F15: =#REF! -> #REF! | G15: =#REF! -> #REF! | H15: =SUM(D15:G15) -> #REF! | I15: =#REF! -> #REF! | J15: =#REF! -> #REF! | K15: =#REF! -> #REF! | L15: =#REF! -> #REF! | M15: =#REF! -> #REF! | N15: =SUM(I15:M15) -> #REF! | O15: =#REF! -> #REF! | P15: =#REF! -> #REF! | Q15: =#REF! -> #REF! | R15: =#REF! -> #REF! | S15: =#REF! -> #REF! | T15: =#REF! -> #REF! | U15: =#REF! -> #REF! | V15: =#REF! -> #REF! | ... Y15: =#REF! -> #REF! | Z15: =SUM(O15:Y15) -> #REF! | AA15: =D15+E15+F15+G15+I15+J15+K15+L15+M15+O15+P15+Q15+R15+S15+T15+U15+V15+W15+X15+Y15 -> #REF! | AF15: 08q2 | AG15: =D21 -> #REF! | AH15: =E21 -> #REF! | AI15: =F21 -> #REF! | AJ15: =G21 -> #REF! | AL15: =I21 -> #REF! | AM15: =J21 -> #REF! | AN15: =K21 -> #REF! | AO15: =L21 -> #REF! | AP15: =M21 -> #REF! | AR15: =O21 -> #REF! | AS15: =P21 -> #REF! | AT15: =Q21 -> #REF! | AU15: =R21 -> #REF! | AV15: =S21 -> #REF! | AW15: =T21 -> #REF! | AX15: =U21 -> #REF! | AY15: =V21 -> #REF! | ... BB15: =Y21 -> #REF!
B16: 2007 | C16: Q1 | D16: =#REF! -> #REF! | E16: =#REF! -> #REF! | F16: =#REF! -> #REF! | G16: =#REF! -> #REF! | H16: =SUM(D16:G16) -> #REF! | I16: =#REF! -> #REF! | J16: =#REF! -> #REF! | K16: =#REF! -> #REF! | L16: =#REF! -> #REF! | M16: =#REF! -> #REF! | N16: =SUM(I16:M16) -> #REF! | O16: =#REF! -> #REF! | P16: =#REF! -> #REF! | Q16: =#REF! -> #REF! | R16: =#REF! -> #REF! | S16: =#REF! -> #REF! | T16: =#REF! -> #REF! | U16: =#REF! -> #REF! | V16: =#REF! -> #REF! | ... Y16: =#REF! -> #REF! | Z16: =SUM(O16:Y16) -> #REF! | AA16: =D16+E16+F16+G16+I16+J16+K16+L16+M16+O16+P16+Q16+R16+S16+T16+U16+V16+W16+X16+Y16 -> #REF! | AF16: 08q3 | AG16: =D22 -> #REF! | AH16: =E22 -> #REF! | AI16: =F22 -> #REF! | AJ16: =G22 -> #REF! | AL16: =I22 -> #REF! | AM16: =J22 -> #REF! | AN16: =K22 -> #REF! | AO16: =L22 -> #REF! | AP16: =M22 -> #REF! | AR16: =O22 -> #REF! | AS16: =P22 -> #REF! | AT16: =Q22 -> #REF! | AU16: =R22 -> #REF! | AV16: =S22 -> #REF! | AW16: =T22 -> #REF! | AX16: =U22 -> #REF! | AY16: =V22 -> #REF! | ... BB16: =Y22 -> #REF!
C17: Q2 | D17: =#REF! -> #REF! | E17: =#REF! -> #REF! | F17: =#REF! -> #REF! | G17: =#REF! -> #REF! | H17: =SUM(D17:G17) -> #REF! | I17: =#REF! -> #REF! | J17: =#REF! -> #REF! | K17: =#REF! -> #REF! | L17: =#REF! -> #REF! | M17: =#REF! -> #REF! | N17: =SUM(I17:M17) -> #REF! | O17: =#REF! -> #REF! | P17: =#REF! -> #REF! | Q17: =#REF! -> #REF! | R17: =#REF! -> #REF! | S17: =#REF! -> #REF! | T17: =#REF! -> #REF! | U17: =#REF! -> #REF! | V17: =#REF! -> #REF! | ... Y17: =#REF! -> #REF! | Z17: =SUM(O17:Y17) -> #REF! | AA17: =D17+E17+F17+G17+I17+J17+K17+L17+M17+O17+P17+Q17+R17+S17+T17+U17+V17+W17+X17+Y17 -> #REF! | AF17: 08q4 | AG17: =D23 -> #REF! | AH17: =E23 -> #REF! | AI17: =F23 -> #REF! | AJ17: =G23 -> #REF! | AL17: =I23 -> #REF! | AM17: =J23 -> #REF! | AN17: =K23 -> #REF! | AO17: =L23 -> #REF! | AP17: =M23 -> #REF! | AR17: =O23 -> #REF! | AS17: =P23 -> #REF! | AT17: =Q23 -> #REF! | AU17: =R23 -> #REF! | AV17: =S23 -> #REF! | AW17: =T23 -> #REF! | AX17: =U23 -> #REF! | AY17: =V23 -> #REF! | ... BB17: =Y23 -> #REF!
C18: Q3 | D18: =#REF! -> #REF! | E18: =#REF! -> #REF! | F18: =#REF! -> #REF! | G18: =#REF! -> #REF! | H18: =SUM(D18:G18) -> #REF! | I18: =#REF! -> #REF! | J18: =#REF! -> #REF! | K18: =#REF! -> #REF! | L18: =#REF! -> #REF! | M18: =#REF! -> #REF! | N18: =SUM(I18:M18) -> #REF! | O18: =#REF! -> #REF! | P18: =#REF! -> #REF! | Q18: =#REF! -> #REF! | R18: =#REF! -> #REF! | S18: =#REF! -> #REF! | T18: =#REF! -> #REF! | U18: =#REF! -> #REF! | V18: =#REF! -> #REF! | ... Y18: =#REF! -> #REF! | Z18: =SUM(O18:Y18) -> #REF! | AA18: =D18+E18+F18+G18+I18+J18+K18+L18+M18+O18+P18+Q18+R18+S18+T18+U18+V18+W18+X18+Y18 -> #REF! | AF18: 09q1 | AG18: =D24 -> #REF! | AH18: =E24 -> #REF! | AI18: =F24 -> #REF! | AJ18: =G24 -> #REF! | AL18: =I24 -> #REF! | AM18: =J24 -> #REF! | AN18: =K24 -> #REF! | AO18: =L24 -> #REF! | AP18: =M24 -> #REF! | AR18: =O24 -> #REF! | AS18: =P24 -> #REF! | AT18: =Q24 -> #REF! | AU18: =R24 -> #REF! | AV18: =S24 -> #REF! | AW18: =T24 -> #REF! | AX18: =U24 -> #REF! | AY18: =V24 -> #REF! | ... BB18: =Y24 -> #REF!
C19: Q4 | D19: =#REF! -> #REF! | E19: =#REF! -> #REF! | F19: =#REF! -> #REF! | G19: =#REF! -> #REF! | H19: =SUM(D19:G19) -> #REF! | I19: =#REF! -> #REF! | J19: =#REF! -> #REF! | K19: =#REF! -> #REF! | L19: =#REF! -> #REF! | M19: =#REF! -> #REF! | N19: =SUM(I19:M19) -> #REF! | O19: =#REF! -> #REF! | P19: =#REF! -> #REF! | Q19: =#REF! -> #REF! | R19: =#REF! -> #REF! | S19: =#REF! -> #REF! | T19: =#REF! -> #REF! | U19: =#REF! -> #REF! | V19: =#REF! -> #REF! | ... Y19: =#REF! -> #REF! | Z19: =SUM(O19:Y19) -> #REF! | AA19: =D19+E19+F19+G19+I19+J19+K19+L19+M19+O19+P19+Q19+R19+S19+T19+U19+V19+W19+X19+Y19 -> #REF! | AF19: 09q2 | AG19: =D25 -> #REF! | AH19: =E25 -> #REF! | AI19: =F25 -> #REF! | AJ19: =G25 -> #REF! | AL19: =I25 -> #REF! | AM19: =J25 -> #REF! | AN19: =K25 -> #REF! | AO19: =L25 -> #REF! | AP19: =M25 -> #REF! | AR19: =O25 -> #REF! | AS19: =P25 -> #REF! | AT19: =Q25 -> #REF! | AU19: =R25 -> #REF! | AV19: =S25 -> #REF! | AW19: =T25 -> #REF! | AX19: =U25 -> #REF! | AY19: =V25 -> #REF! | ... BB19: =Y25 -> #REF!
B20: 2008 | C20: Q1 | D20: =#REF! -> #REF! | E20: =#REF! -> #REF! | F20: =#REF! -> #REF! | G20: =#REF! -> #REF! | H20: =SUM(D20:G20) -> #REF! | I20: =#REF! -> #REF! | J20: =#REF! -> #REF! | K20: =#REF! -> #REF! | L20: =#REF! -> #REF! | M20: =#REF! -> #REF! | N20: =SUM(I20:M20) -> #REF! | O20: =#REF! -> #REF! | P20: =#REF! -> #REF! | Q20: =#REF! -> #REF! | R20: =#REF! -> #REF! | S20: =#REF! -> #REF! | T20: =#REF! -> #REF! | U20: =#REF! -> #REF! | V20: =#REF! -> #REF! | ... Y20: =#REF! -> #REF! | Z20: =SUM(O20:Y20) -> #REF! | AA20: =D20+E20+F20+G20+I20+J20+K20+L20+M20+O20+P20+Q20+R20+S20+T20+U20+V20+W20+X20+Y20 -> #REF! | AF20: 09q3 | AG20: =D26 -> #REF! | AH20: =E26 -> #REF! | AI20: =F26 -> #REF! | AJ20: =G26 -> #REF! | AL20: =I26 -> #REF! | AM20: =J26 -> #REF! | AN20: =K26 -> #REF! | AO20: =L26 -> #REF! | AP20: =M26 -> #REF! | AR20: =O26 -> #REF! | AS20: =P26 -> #REF! | AT20: =Q26 -> #REF! | AU20: =R26 -> #REF! | AV20: =S26 -> #REF! | AW20: =T26 -> #REF! | AX20: =U26 -> #REF! | AY20: =V26 -> #REF! | ... BB20: =Y26 -> #REF!
C21: Q2 | D21: =#REF! -> #REF! | E21: =#REF! -> #REF! | F21: =#REF! -> #REF! | G21: =#REF! -> #REF! | H21: =SUM(D21:G21) -> #REF! | I21: =#REF! -> #REF! | J21: =#REF! -> #REF! | K21: =#REF! -> #REF! | L21: =#REF! -> #REF! | M21: =#REF! -> #REF! | N21: =SUM(I21:M21) -> #REF! | O21: =#REF! -> #REF! | P21: =#REF! -> #REF! | Q21: =#REF! -> #REF! | R21: =#REF! -> #REF! | S21: =#REF! -> #REF! | T21: =#REF! -> #REF! | U21: =#REF! -> #REF! | V21: =#REF! -> #REF! | ... Y21: =#REF! -> #REF! | Z21: =SUM(O21:Y21) -> #REF! | AA21: =D21+E21+F21+G21+I21+J21+K21+L21+M21+O21+P21+Q21+R21+S21+T21+U21+V21+W21+X21+Y21 -> #REF! | AF21: 09q4 | AG21: =D27 -> #REF! | AH21: =E27 -> #REF! | AI21: =F27 -> #REF! | AJ21: =G27 -> #REF! | AL21: =I27 -> #REF! | AM21: =J27 -> #REF! | AN21: =K27 -> #REF! | AO21: =L27 -> #REF! | AP21: =M27 -> #REF! | AR21: =O27 -> #REF! | AS21: =P27 -> #REF! | AT21: =Q27 -> #REF! | AU21: =R27 -> #REF! | AV21: =S27 -> #REF! | AW21: =T27 -> #REF! | AX21: =U27 -> #REF! | AY21: =V27 -> #REF! | ... BB21: =Y27 -> #REF!
C22: Q3 | D22: =#REF! -> #REF! | E22: =#REF! -> #REF! | F22: =#REF! -> #REF! | G22: =#REF! -> #REF! | H22: =SUM(D22:G22) -> #REF! | I22: =#REF! -> #REF! | J22: =#REF! -> #REF! | K22: =#REF! -> #REF! | L22: =#REF! -> #REF! | M22: =#REF! -> #REF! | N22: =SUM(I22:M22) -> #REF! | O22: =#REF! -> #REF! | P22: =#REF! -> #REF! | Q22: =#REF! -> #REF! | R22: =#REF! -> #REF! | S22: =#REF! -> #REF! | T22: =#REF! -> #REF! | U22: =#REF! -> #REF! | V22: =#REF! -> #REF! | ... Y22: =#REF! -> #REF! | Z22: =SUM(O22:Y22) -> #REF! | AA22: =D22+E22+F22+G22+I22+J22+K22+L22+M22+O22+P22+Q22+R22+S22+T22+U22+V22+W22+X22+Y22 -> #REF! | AF22: 10q1 | AG22: =D28 -> #REF! | AH22: =E28 -> #REF! | AI22: =F28 -> #REF! | AJ22: =G28 -> #REF! | AL22: =I28 -> #REF! | AM22: =J28 -> #REF! | AN22: =K28 -> #REF! | AO22: =L28 -> #REF! | AP22: =M28 -> #REF! | AR22: =O28 -> #REF! | AS22: =P28 -> #REF! | AT22: =Q28 -> #REF! | AU22: =R28 -> #REF! | AV22: =S28 -> #REF! | AW22: =T28 -> #REF! | AX22: =U28 -> #REF! | AY22: =V28 -> #REF! | ... BB22: =Y28 -> #REF!
C23: Q4 | D23: =#REF! -> #REF! | E23: =#REF! -> #REF! | F23: =#REF! -> #REF! | G23: =#REF! -> #REF! | H23: =SUM(D23:G23) -> #REF! | I23: =#REF! -> #REF! | J23: =#REF! -> #REF! | K23: =#REF! -> #REF! | L23: =#REF! -> #REF! | M23: =#REF! -> #REF! | N23: =SUM(I23:M23) -> #REF! | O23: =#REF! -> #REF! | P23: =#REF! -> #REF! | Q23: =#REF! -> #REF! | R23: =#REF! -> #REF! | S23: =#REF! -> #REF! | T23: =#REF! -> #REF! | U23: =#REF! -> #REF! | V23: =#REF! -> #REF! | ... Y23: =#REF! -> #REF! | Z23: =SUM(O23:Y23) -> #REF! | AA23: =D23+E23+F23+G23+I23+J23+K23+L23+M23+O23+P23+Q23+R23+S23+T23+U23+V23+W23+X23+Y23 -> #REF! | AF23: 10q2 | AG23: =D29 -> #REF! | AH23: =E29 -> #REF! | AI23: =F29 -> #REF! | AJ23: =G29 -> #REF! | AL23: =I29 -> #REF! | AM23: =J29 -> #REF! | AN23: =K29 -> #REF! | AO23: =L29 -> #REF! | AP23: =M29 -> #REF! | AR23: =O29 -> #REF! | AS23: =P29 -> #REF! | AT23: =Q29 -> #REF! | AU23: =R29 -> #REF! | AV23: =S29 -> #REF! | AW23: =T29 -> #REF! | AX23: =U29 -> #REF! | AY23: =V29 -> #REF! | ... BB23: =Y29 -> #REF!
B24: 2009 | C24: Q1 | D24: =#REF! -> #REF! | E24: =#REF! -> #REF! | F24: =#REF! -> #REF! | G24: =#REF! -> #REF! | H24: =SUM(D24:G24) -> #REF! | I24: =#REF! -> #REF! | J24: =#REF! -> #REF! | K24: =#REF! -> #REF! | L24: =#REF! -> #REF! | M24: =#REF! -> #REF! | N24: =SUM(I24:M24) -> #REF! | O24: =#REF! -> #REF! | P24: =#REF! -> #REF! | Q24: =#REF! -> #REF! | R24: =#REF! -> #REF! | S24: =#REF! -> #REF! | T24: =#REF! -> #REF! | U24: =#REF! -> #REF! | V24: =#REF! -> #REF! | ... Y24: =#REF! -> #REF! | Z24: =SUM(O24:Y24) -> #REF! | AA24: =D24+E24+F24+G24+I24+J24+K24+L24+M24+O24+P24+Q24+R24+S24+T24+U24+V24+W24+X24+Y24 -> #REF! | AF24: 10q3 | AG24: =D30 -> #REF! | AH24: =E30 -> #REF! | AI24: =F30 -> #REF! | AJ24: =G30 -> #REF! | AL24: =I30 -> #REF! | AM24: =J30 -> #REF! | AN24: =K30 -> #REF! | AO24: =L30 -> #REF! | AP24: =M30 -> #REF! | AR24: =O30 -> #REF! | AS24: =P30 -> #REF! | AT24: =Q30 -> #REF! | AU24: =R30 -> #REF! | AV24: =S30 -> #REF! | AW24: =T30 -> #REF! | AX24: =U30 -> #REF! | AY24: =V30 -> #REF! | ... BB24: =Y30 -> #REF!
C25: Q2 | D25: =#REF! -> #REF! | E25: =#REF! -> #REF! | F25: =#REF! -> #REF! | G25: =#REF! -> #REF! | H25: =SUM(D25:G25) -> #REF! | I25: =#REF! -> #REF! | J25: =#REF! -> #REF! | K25: =#REF! -> #REF! | L25: =#REF! -> #REF! | M25: =#REF! -> #REF! | N25: =SUM(I25:M25) -> #REF! | O25: =#REF! -> #REF! | P25: =#REF! -> #REF! | Q25: =#REF! -> #REF! | R25: =#REF! -> #REF! | S25: =#REF! -> #REF! | T25: =#REF! -> #REF! | U25: =#REF! -> #REF! | V25: =#REF! -> #REF! | ... Y25: =#REF! -> #REF! | Z25: =SUM(O25:Y25) -> #REF! | AA25: =D25+E25+F25+G25+I25+J25+K25+L25+M25+O25+P25+Q25+R25+S25+T25+U25+V25+W25+X25+Y25 -> #REF! | AF25: 10q4 | AG25: =D31 -> #REF! | AH25: =E31 -> #REF! | AI25: =F31 -> #REF! | AJ25: =G31 -> #REF! | AL25: =I31 -> #REF! | AM25: =J31 -> #REF! | AN25: =K31 -> #REF! | AO25: =L31 -> #REF! | AP25: =M31 -> #REF! | AR25: =O31 -> #REF! | AS25: =P31 -> #REF! | AT25: =Q31 -> #REF! | AU25: =R31 -> #REF! | AV25: =S31 -> #REF! | AW25: =T31 -> #REF! | AX25: =U31 -> #REF! | AY25: =V31 -> #REF! | ... BB25: =Y31 -> #REF!
